Workbook
Name Binary: Table6[Binary]
Name Dead_Wood_Classes: DWC[Dead Wood Classes]
Name LookupNames: Table1[Lookup name]
Name Tree_Category: TreeCategory[[#Headers],[Tree Category]]
Name TreeCat: TreeCategory[Tree Category]

Sheet PSP Data
B1: PSP Plot Number
B2: Field Observation Date [dd.mm.yy]
B3: Start time [HH:MM]
B4: End time [HH:MM]
B5: Field Reporters (team members separate with comma)
B6: Digitalization Date [dd.mm.yyy]
B7: Digitalized by
A8: Coordinates | B8: X
B9: Y
A10: Tag | B10: Initial
B11: First used in outter circle
B12: Final
B13: Observations
A22: Trees | K22: Lying Deadwood
A23: Tag Number | B23: Species | C23: DBH | D23: Flower | E23: Seed | F23: Fruit | G23: X coordinate | H23: Y coordinate | I23: POM(cm) | K23: Dead Wood Class | L23: Dimater | M23: Hollow

Sheet Analysis
A1: Hour man costs | Y1: List of timber species | AC1: List of flowering trees | AG1: List of trees with fruits
A2: hours | B2: members | C2: hour man | Y2: unique | AC2: unique | AG2: unique
A3: ='PSP Data'!C4-'PSP Data'!C3 -> 0 | B3: =LEN(TRIM('PSP Data'!C5))-LEN(SUBSTITUTE(TRIM('PSP Data'!C5),",",""))+1 -> 1 | C3: =A3*B3 -> 0 | T3: Row Labels | U3: Sum of Count_cat | V3: Row Labels | W3: Sum of Count_dead | Y3: {=INDEX($N$21:$N$900, MATCH(0, COUNTIF($Y$2:Y2, $N$21:$N$900), 0))} -> #N/A | AC3: {=INDEX($O$21:$O$900, MATCH(0, COUNTIF($AC$2:AC2, $O$21:$O$900), 0))} | AG3: {=INDEX($P$21:$P$900, MATCH(0, COUNTIF($AG$2:AG2, $P$21:$P$900), 0))}
T4: habitat | U4: 20 | V4: FALSE | W4: 27 | Y4: {=INDEX($N$21:$N$900, MATCH(0, COUNTIF($Y$2:Y3, $N$21:$N$900), 0))} -> #N/A | AC4: {=INDEX($O$21:$O$900, MATCH(0, COUNTIF($AC$2:AC3, $O$21:$O$900), 0))} -> #N/A | AG4: {=INDEX($P$21:$P$900, MATCH(0, COUNTIF($AG$2:AG3, $P$21:$P$900), 0))} -> #N/A
A5: Number of tagged trees | T5: medicinal | U5: 2 | V5: TRUE | W5: 5 | Y5: {=INDEX($N$21:$N$900, MATCH(0, COUNTIF($Y$2:Y4, $N$21:$N$900), 0))} -> #N/A | AC5: {=INDEX($O$21:$O$900, MATCH(0, COUNTIF($AC$2:AC4, $O$21:$O$900), 0))} -> #N/A | AG5: {=INDEX($P$21:$P$900, MATCH(0, COUNTIF($AG$2:AG4, $P$21:$P$900), 0))} -> #N/A
A6: inner | B6: outter | C6: total | T6: timber | U6: 4 | V6: Grand Total | W6: 32 | Y6: {=INDEX($N$21:$N$900, MATCH(0, COUNTIF($Y$2:Y5, $N$21:$N$900), 0))} -> #N/A | AC6: {=INDEX($O$21:$O$900, MATCH(0, COUNTIF($AC$2:AC5, $O$21:$O$900), 0))} -> #N/A | AG6: {=INDEX($P$21:$P$900, MATCH(0, COUNTIF($AG$2:AG5, $P$21:$P$900), 0))} -> #N/A
A7: ='PSP Data'!C11-'PSP Data'!C10 -> 0 | B7: ='PSP Data'!C12-'PSP Data'!C11 -> 0 | C7: ='PSP Data'!C12-'PSP Data'!C10 -> 0 | T7: unknown | U7: 6 | Y7: {=INDEX($N$21:$N$900, MATCH(0, COUNTIF($Y$2:Y6, $N$21:$N$900), 0))} -> #N/A | AC7: {=INDEX($O$21:$O$900, MATCH(0, COUNTIF($AC$2:AC6, $O$21:$O$900), 0))} -> #N/A | AG7: {=INDEX($P$21:$P$900, MATCH(0, COUNTIF($AG$2:AG6, $P$21:$P$900), 0))} -> #N/A
T8: Grand Total | U8: 32 | Y8: {=INDEX($N$21:$N$900, MATCH(0, COUNTIF($Y$2:Y7, $N$21:$N$900), 0))} -> #N/A | AC8: {=INDEX($O$21:$O$900, MATCH(0, COUNTIF($AC$2:AC7, $O$21:$O$900), 0))} -> #N/A | AG8: {=INDEX($P$21:$P$900, MATCH(0, COUNTIF($AG$2:AG7, $P$21:$P$900), 0))} -> #N/A
A9: Most occuring tree | Y9: {=INDEX($N$21:$N$900, MATCH(0, COUNTIF($Y$2:Y8, $N$21:$N$900), 0))} -> #N/A | AC9: {=INDEX($O$21:$O$900, MATCH(0, COUNTIF($AC$2:AC8, $O$21:$O$900), 0))} -> #N/A | AG9: {=INDEX($P$21:$P$900, MATCH(0, COUNTIF($AG$2:AG8, $P$21:$P$900), 0))} -> #N/A
A10: {=INDEX(B21:B900,MODE(IF(B21:B900<>"",MATCH(B21:B900,B21:B900,0))))} -> #N/A | Y10: {=INDEX($N$21:$N$900, MATCH(0, COUNTIF($Y$2:Y9, $N$21:$N$900), 0))} -> #N/A | AC10: {=INDEX($O$21:$O$900, MATCH(0, COUNTIF($AC$2:AC9, $O$21:$O$900), 0))} -> #N/A | AG10: {=INDEX($P$21:$P$900, MATCH(0, COUNTIF($AG$2:AG9, $P$21:$P$900), 0))} -> #N/A
Y11: {=INDEX($N$21:$N$900, MATCH(0, COUNTIF($Y$2:Y10, $N$21:$N$900), 0))} -> #N/A | AC11: {=INDEX($O$21:$O$900, MATCH(0, COUNTIF($AC$2:AC10, $O$21:$O$900), 0))} -> #N/A | AG11: {=INDEX($P$21:$P$900, MATCH(0, COUNTIF($AG$2:AG10, $P$21:$P$900), 0))} -> #N/A
Y12: {=INDEX($N$21:$N$900, MATCH(0, COUNTIF($Y$2:Y11, $N$21:$N$900), 0))} -> #N/A | AC12: {=INDEX($O$21:$O$900, MATCH(0, COUNTIF($AC$2:AC11, $O$21:$O$900), 0))} -> #N/A | AG12: {=INDEX($P$21:$P$900, MATCH(0, COUNTIF($AG$2:AG11, $P$21:$P$900), 0))} -> #N/A
Y13: {=INDEX($N$21:$N$900, MATCH(0, COUNTIF($Y$2:Y12, $N$21:$N$900), 0))} -> #N/A | AC13: {=INDEX($O$21:$O$900, MATCH(0, COUNTIF($AC$2:AC12, $O$21:$O$900), 0))} -> #N/A | AG13: {=INDEX($P$21:$P$900, MATCH(0, COUNTIF($AG$2:AG12, $P$21:$P$900), 0))} -> #N/A
Y14: {=INDEX($N$21:$N$900, MATCH(0, COUNTIF($Y$2:Y13, $N$21:$N$900), 0))} -> #N/A | AC14: {=INDEX($O$21:$O$900, MATCH(0, COUNTIF($AC$2:AC13, $O$21:$O$900), 0))} -> #N/A | AG14: {=INDEX($P$21:$P$900, MATCH(0, COUNTIF($AG$2:AG13, $P$21:$P$900), 0))} -> #N/A
Y15: {=INDEX($N$21:$N$900, MATCH(0, COUNTIF($Y$2:Y14, $N$21:$N$900), 0))} -> #N/A | AC15: {=INDEX($O$21:$O$900, MATCH(0, COUNTIF($AC$2:AC14, $O$21:$O$900), 0))} -> #N/A | AG15: {=INDEX($P$21:$P$900, MATCH(0, COUNTIF($AG$2:AG14, $P$21:$P$900), 0))} -> #N/A
Y16: {=INDEX($N$21:$N$900, MATCH(0, COUNTIF($Y$2:Y15, $N$21:$N$900), 0))} -> #N/A | AC16: {=INDEX($O$21:$O$900, MATCH(0, COUNTIF($AC$2:AC15, $O$21:$O$900), 0))} -> #N/A | AG16: {=INDEX($P$21:$P$900, MATCH(0, COUNTIF($AG$2:AG15, $P$21:$P$900), 0))} -> #N/A
Y17: {=INDEX($N$21:$N$900, MATCH(0, COUNTIF($Y$2:Y16, $N$21:$N$900), 0))} -> #N/A | AC17: {=INDEX($O$21:$O$900, MATCH(0, COUNTIF($AC$2:AC16, $O$21:$O$900), 0))} -> #N/A | AG17: {=INDEX($P$21:$P$900, MATCH(0, COUNTIF($AG$2:AG16, $P$21:$P$900), 0))} -> #N/A
Y18: {=INDEX($N$21:$N$900, MATCH(0, COUNTIF($Y$2:Y17, $N$21:$N$900), 0))} -> #N/A | AC18: {=INDEX($O$21:$O$900, MATCH(0, COUNTIF($AC$2:AC17, $O$21:$O$900), 0))} -> #N/A | AG18: {=INDEX($P$21:$P$900, MATCH(0, COUNTIF($AG$2:AG17, $P$21:$P$900), 0))} -> #N/A
A19: DATA COPY AND MANIPULATION | Y19: {=INDEX($N$21:$N$900, MATCH(0, COUNTIF($Y$2:Y18, $N$21:$N$900), 0))} -> #N/A | AC19: {=INDEX($O$21:$O$900, MATCH(0, COUNTIF($AC$2:AC18, $O$21:$O$900), 0))} -> #N/A | AG19: {=INDEX($P$21:$P$900, MATCH(0, COUNTIF($AG$2:AG18, $P$21:$P$900), 0))} -> #N/A
A20: ='PSP Data'!A23 -> Tag Number | B20: ='PSP Data'!B23 -> Species | C20: ='PSP Data'!C23 -> DBH | D20: ='PSP Data'!D23 -> Flower | E20: ='PSP Data'!E23 -> Seed | F20: ='PSP Data'!F23 -> Fruit | G20: ='PSP Data'!G23 -> X coordinate | H20: ='PSP Data'!H23 -> Y coordinate | I20: ='PSP Data'!I23 -> POM(cm) | J20: DBH(>25) | K20: DBH inner | L20: Category | M20: Count_cat | N20: Timber species | O20: Trees with Flower | P20: Trees with Fruit | Q20: Is Deadwood? | R20: Count_dead | Y20: {=INDEX($N$21:$N$900, MATCH(0, COUNTIF($Y$2:Y19, $N$21:$N$900), 0))} -> #N/A | AC20: {=INDEX($O$21:$O$900, MATCH(0, COUNTIF($AC$2:AC19, $O$21:$O$900), 0))} -> #N/A | AG20: {=INDEX($P$21:$P$900, MATCH(0, COUNTIF($AG$2:AG19, $P$21:$P$900), 0))} -> #N/A
A21: ='PSP Data'!A24 -> 0 | B21: =IF('PSP Data'!B24=0,"",'PSP Data'!B24) | C21: ='PSP Data'!C24 -> 0 | D21: ='PSP Data'!D24 -> 0 | E21: ='PSP Data'!E24 -> 0 | F21: ='PSP Data'!F24 -> 0 | G21: ='PSP Data'!G24 -> 0 | H21: ='PSP Data'!H24 -> 0 | I21: ='PSP Data'!I24 -> 0 | J21: =IF(C21>=25,C21,#N/A) -> #N/A | K21: =IF(AND((A21<'PSP Data'!$C$11),(A21<>0)),Analysis!C21,#N/A) -> #N/A | L21: =IF(VLOOKUP(B21,Table1[],4)=0,"unknown", VLOOKUP(B21,Table1[],4)) -> #N/A | M21: 1 | N21: =IF(L21="timber",B21,"") -> #N/A | O21: =IF(D21="y",B21,"") | P21: =IF(F21="y",B21,"") | Q21: =IF(B21="","",ISNUMBER(FIND("Dead wood",B21:B900))) | R21: 1 | Y21: {=INDEX($N$21:$N$900, MATCH(0, COUNTIF($Y$2:Y20, $N$21:$N$900), 0))} -> #N/A | AC21: {=INDEX($O$21:$O$900, MATCH(0, COUNTIF($AC$2:AC20, $O$21:$O$900), 0))} -> #N/A | AG21: {=INDEX($P$21:$P$900, MATCH(0, COUNTIF($AG$2:AG20, $P$21:$P$900), 0))} -> #N/A
A22: ='PSP Data'!A25 -> 0 | B22: =IF('PSP Data'!B25=0,"",'PSP Data'!B25) | C22: ='PSP Data'!C25 -> 0 | D22: ='PSP Data'!D25 -> 0 | E22: ='PSP Data'!E25 -> 0 | F22: ='PSP Data'!F25 -> 0 | G22: ='PSP Data'!G25 -> 0 | H22: ='PSP Data'!H25 -> 0 | I22: ='PSP Data'!I25 -> 0 | J22: =IF(C22>=25,C22,#N/A) -> #N/A | K22: =IF(AND((A22<'PSP Data'!$C$11),(A22<>0)),Analysis!C22,#N/A) -> #N/A | L22: =IF(VLOOKUP(B22,Table1[],4)=0,"unknown", VLOOKUP(B22,Table1[],4)) -> #N/A | M22: 1 | N22: =IF(L22="timber",B22,"") -> #N/A | O22: =IF(D22="y",B22,"") | P22: =IF(F22="y",B22,"") | Q22: =IF(B22="","",ISNUMBER(FIND("Dead wood",B22:B901))) | R22: 1 | Y22: {=INDEX($N$21:$N$900, MATCH(0, COUNTIF($Y$2:Y21, $N$21:$N$900), 0))} -> #N/A | AC22: {=INDEX($O$21:$O$900, MATCH(0, COUNTIF($AC$2:AC21, $O$21:$O$900), 0))} -> #N/A | AG22: {=INDEX($P$21:$P$900, MATCH(0, COUNTIF($AG$2:AG21, $P$21:$P$900), 0))} -> #N/A
A23: ='PSP Data'!A26 -> 0 | B23: =IF('PSP Data'!B26=0,"",'PSP Data'!B26) | C23: ='PSP Data'!C26 -> 0 | D23: ='PSP Data'!D26 -> 0 | E23: ='PSP Data'!E26 -> 0 | F23: ='PSP Data'!F26 -> 0 | G23: ='PSP Data'!G26 -> 0 | H23: ='PSP Data'!H26 -> 0 | I23: ='PSP Data'!I26 -> 0 | J23: =IF(C23>=25,C23,#N/A) -> #N/A | K23: =IF(AND((A23<'PSP Data'!$C$11),(A23<>0)),Analysis!C23,#N/A) -> #N/A | L23: =IF(VLOOKUP(B23,Table1[],4)=0,"unknown", VLOOKUP(B23,Table1[],4)) -> #N/A | M23: 1 | N23: =IF(L23="timber",B23,"") -> #N/A | O23: =IF(D23="y",B23,"") | P23: =IF(F23="y",B23,"") | Q23: =IF(B23="","",ISNUMBER(FIND("Dead wood",B23:B902))) | R23: 1 | Y23: {=INDEX($N$21:$N$900, MATCH(0, COUNTIF($Y$2:Y22, $N$21:$N$900), 0))} -> #N/A | AC23: {=INDEX($O$21:$O$900, MATCH(0, COUNTIF($AC$2:AC22, $O$21:$O$900), 0))} -> #N/A | AG23: {=INDEX($P$21:$P$900, MATCH(0, COUNTIF($AG$2:AG22, $P$21:$P$900), 0))} -> #N/A
A24: ='PSP Data'!A27 -> 0 | B24: =IF('PSP Data'!B27=0,"",'PSP Data'!B27) | C24: ='PSP Data'!C27 -> 0 | D24: ='PSP Data'!D27 -> 0 | E24: ='PSP Data'!E27 -> 0 | F24: ='PSP Data'!F27 -> 0 | G24: ='PSP Data'!G27 -> 0 | H24: ='PSP Data'!H27 -> 0 | I24: ='PSP Data'!I27 -> 0 | J24: =IF(C24>=25,C24,#N/A) -> #N/A | K24: =IF(AND((A24<'PSP Data'!$C$11),(A24<>0)),Analysis!C24,#N/A) -> #N/A | L24: =IF(VLOOKUP(B24,Table1[],4)=0,"unknown", VLOOKUP(B24,Table1[],4)) -> #N/A | M24: 1 | N24: =IF(L24="timber",B24,"") -> #N/A | O24: =IF(D24="y",B24,"") | P24: =IF(F24="y",B24,"") | Q24: =IF(B24="","",ISNUMBER(FIND("Dead wood",B24:B903))) | R24: 1 | Y24: {=INDEX($N$21:$N$900, MATCH(0, COUNTIF($Y$2:Y23, $N$21:$N$900), 0))} -> #N/A | AC24: {=INDEX($O$21:$O$900, MATCH(0, COUNTIF($AC$2:AC23, $O$21:$O$900), 0))} -> #N/A | AG24: {=INDEX($P$21:$P$900, MATCH(0, COUNTIF($AG$2:AG23, $P$21:$P$900), 0))} -> #N/A
A25: ='PSP Data'!A28 -> 0 | B25: =IF('PSP Data'!B28=0,"",'PSP Data'!B28) | C25: ='PSP Data'!C28 -> 0 | D25: ='PSP Data'!D28 -> 0 | E25: ='PSP Data'!E28 -> 0 | F25: ='PSP Data'!F28 -> 0 | G25: ='PSP Data'!G28 -> 0 | H25: ='PSP Data'!H28 -> 0 | I25: ='PSP Data'!I28 -> 0 | J25: =IF(C25>=25,C25,#N/A) -> #N/A | K25: =IF(AND((A25<'PSP Data'!$C$11),(A25<>0)),Analysis!C25,#N/A) -> #N/A | L25: =IF(VLOOKUP(B25,Table1[],4)=0,"unknown", VLOOKUP(B25,Table1[],4)) -> #N/A | M25: 1 | N25: =IF(L25="timber",B25,"") -> #N/A | O25: =IF(D25="y",B25,"") | P25: =IF(F25="y",B25,"") | Q25: =IF(B25="","",ISNUMBER(FIND("Dead wood",B25:B904))) | R25: 1 | Y25: {=INDEX($N$21:$N$900, MATCH(0, COUNTIF($Y$2:Y24, $N$21:$N$900), 0))} -> #N/A | AC25: {=INDEX($O$21:$O$900, MATCH(0, COUNTIF($AC$2:AC24, $O$21:$O$900), 0))} -> #N/A | AG25: {=INDEX($P$21:$P$900, MATCH(0, COUNTIF($AG$2:AG24, $P$21:$P$900), 0))} -> #N/A
A26: ='PSP Data'!A29 -> 0 | B26: =IF('PSP Data'!B29=0,"",'PSP Data'!B29) | C26: ='PSP Data'!C29 -> 0 | D26: ='PSP Data'!D29 -> 0 | E26: ='PSP Data'!E29 -> 0 | F26: ='PSP Data'!F29 -> 0 | G26: ='PSP Data'!G29 -> 0 | H26: ='PSP Data'!H29 -> 0 | I26: ='PSP Data'!I29 -> 0 | J26: =IF(C26>=25,C26,#N/A) -> #N/A | K26: =IF(AND((A26<'PSP Data'!$C$11),(A26<>0)),Analysis!C26,#N/A) -> #N/A | L26: =IF(VLOOKUP(B26,Table1[],4)=0,"unknown", VLOOKUP(B26,Table1[],4)) -> #N/A | M26: 1 | N26: =IF(L26="timber",B26,"") -> #N/A | O26: =IF(D26="y",B26,"") | P26: =IF(F26="y",B26,"") | Q26: =IF(B26="","",ISNUMBER(FIND("Dead wood",B26:B905))) | R26: 1 | Y26: {=INDEX($N$21:$N$900, MATCH(0, COUNTIF($Y$2:Y25, $N$21:$N$900), 0))} -> #N/A | AC26: {=INDEX($O$21:$O$900, MATCH(0, COUNTIF($AC$2:AC25, $O$21:$O$900), 0))} -> #N/A | AG26: {=INDEX($P$21:$P$900, MATCH(0, COUNTIF($AG$2:AG25, $P$21:$P$900), 0))} -> #N/A
A27: ='PSP Data'!A30 -> 0 | B27: =IF('PSP Data'!B30=0,"",'PSP Data'!B30) | C27: ='PSP Data'!C30 -> 0 | D27: ='PSP Data'!D30 -> 0 | E27: ='PSP Data'!E30 -> 0 | F27: ='PSP Data'!F30 -> 0 | G27: ='PSP Data'!G30 -> 0 | H27: ='PSP Data'!H30 -> 0 | I27: ='PSP Data'!I30 -> 0 | J27: =IF(C27>=25,C27,#N/A) -> #N/A | K27: =IF(AND((A27<'PSP Data'!$C$11),(A27<>0)),Analysis!C27,#N/A) -> #N/A | L27: =IF(VLOOKUP(B27,Table1[],4)=0,"unknown", VLOOKUP(B27,Table1[],4)) -> #N/A | M27: 1 | N27: =IF(L27="timber",B27,"") -> #N/A | O27: =IF(D27="y",B27,"") | P27: =IF(F27="y",B27,"") | Q27: =IF(B27="","",ISNUMBER(FIND("Dead wood",B27:B906))) | R27: 1 | Y27: {=INDEX($N$21:$N$900, MATCH(0, COUNTIF($Y$2:Y26, $N$21:$N$900), 0))} -> #N/A | AC27: {=INDEX($O$21:$O$900, MATCH(0, COUNTIF($AC$2:AC26, $O$21:$O$900), 0))} -> #N/A | AG27: {=INDEX($P$21:$P$900, MATCH(0, COUNTIF($AG$2:AG26, $P$21:$P$900), 0))} -> #N/A
A28: ='PSP Data'!A31 -> 0 | B28: =IF('PSP Data'!B31=0,"",'PSP Data'!B31) | C28: ='PSP Data'!C31 -> 0 | D28: ='PSP Data'!D31 -> 0 | E28: ='PSP Data'!E31 -> 0 | F28: ='PSP Data'!F31 -> 0 | G28: ='PSP Data'!G31 -> 0 | H28: ='PSP Data'!H31 -> 0 | I28: ='PSP Data'!I31 -> 0 | J28: =IF(C28>=25,C28,#N/A) -> #N/A | K28: =IF(AND((A28<'PSP Data'!$C$11),(A28<>0)),Analysis!C28,#N/A) -> #N/A | L28: =IF(VLOOKUP(B28,Table1[],4)=0,"unknown", VLOOKUP(B28,Table1[],4)) -> #N/A | M28: 1 | N28: =IF(L28="timber",B28,"") -> #N/A | O28: =IF(D28="y",B28,"") | P28: =IF(F28="y",B28,"") | Q28: =IF(B28="","",ISNUMBER(FIND("Dead wood",B28:B907))) | R28: 1 | Y28: {=INDEX($N$21:$N$900, MATCH(0, COUNTIF($Y$2:Y27, $N$21:$N$900), 0))} -> #N/A | AC28: {=INDEX($O$21:$O$900, MATCH(0, COUNTIF($AC$2:AC27, $O$21:$O$900), 0))} -> #N/A | AG28: {=INDEX($P$21:$P$900, MATCH(0, COUNTIF($AG$2:AG27, $P$21:$P$900), 0))} -> #N/A
A29: ='PSP Data'!A32 -> 0 | B29: =IF('PSP Data'!B32=0,"",'PSP Data'!B32) | C29: ='PSP Data'!C32 -> 0 | D29: ='PSP Data'!D32 -> 0 | E29: ='PSP Data'!E32 -> 0 | F29: ='PSP Data'!F32 -> 0 | G29: ='PSP Data'!G32 -> 0 | H29: ='PSP Data'!H32 -> 0 | I29: ='PSP Data'!I32 -> 0 | J29: =IF(C29>=25,C29,#N/A) -> #N/A | K29: =IF(AND((A29<'PSP Data'!$C$11),(A29<>0)),Analysis!C29,#N/A) -> #N/A | L29: =IF(VLOOKUP(B29,Table1[],4)=0,"unknown", VLOOKUP(B29,Table1[],4)) -> #N/A | M29: 1 | N29: =IF(L29="timber",B29,"") -> #N/A | O29: =IF(D29="y",B29,"") | P29: =IF(F29="y",B29,"") | Q29: =IF(B29="","",ISNUMBER(FIND("Dead wood",B29:B908))) | R29: 1 | Y29: {=INDEX($N$21:$N$900, MATCH(0, COUNTIF($Y$2:Y28, $N$21:$N$900), 0))} -> #N/A | AC29: {=INDEX($O$21:$O$900, MATCH(0, COUNTIF($AC$2:AC28, $O$21:$O$900), 0))} -> #N/A | AG29: {=INDEX($P$21:$P$900, MATCH(0, COUNTIF($AG$2:AG28, $P$21:$P$900), 0))} -> #N/A
A30: ='PSP Data'!A33 -> 0 | B30: =IF('PSP Data'!B33=0,"",'PSP Data'!B33) | C30: ='PSP Data'!C33 -> 0 | D30: ='PSP Data'!D33 -> 0 | E30: ='PSP Data'!E33 -> 0 | F30: ='PSP Data'!F33 -> 0 | G30: ='PSP Data'!G33 -> 0 | H30: ='PSP Data'!H33 -> 0 | I30: ='PSP Data'!I33 -> 0 | J30: =IF(C30>=25,C30,#N/A) -> #N/A | K30: =IF(AND((A30<'PSP Data'!$C$11),(A30<>0)),Analysis!C30,#N/A) -> #N/A | L30: =IF(VLOOKUP(B30,Table1[],4)=0,"unknown", VLOOKUP(B30,Table1[],4)) -> #N/A | M30: 1 | N30: =IF(L30="timber",B30,"") -> #N/A | O30: =IF(D30="y",B30,"") | P30: =IF(F30="y",B30,"") | Q30: =IF(B30="","",ISNUMBER(FIND("Dead wood",B30:B909))) | R30: 1 | Y30: {=INDEX($N$21:$N$900, MATCH(0, COUNTIF($Y$2:Y29, $N$21:$N$900), 0))} -> #N/A | AC30: {=INDEX($O$21:$O$900, MATCH(0, COUNTIF($AC$2:AC29, $O$21:$O$900), 0))} -> #N/A | AG30: {=INDEX($P$21:$P$900, MATCH(0, COUNTIF($AG$2:AG29, $P$21:$P$900), 0))} -> #N/A
A31: ='PSP Data'!A34 -> 0 | B31: =IF('PSP Data'!B34=0,"",'PSP Data'!B34) | C31: ='PSP Data'!C34 -> 0 | D31: ='PSP Data'!D34 -> 0 | E31: ='PSP Data'!E34 -> 0 | F31: ='PSP Data'!F34 -> 0 | G31: ='PSP Data'!G34 -> 0 | H31: ='PSP Data'!H34 -> 0 | I31: ='PSP Data'!I34 -> 0 | J31: =IF(C31>=25,C31,#N/A) -> #N/A | K31: =IF(AND((A31<'PSP Data'!$C$11),(A31<>0)),Analysis!C31,#N/A) -> #N/A | L31: =IF(VLOOKUP(B31,Table1[],4)=0,"unknown", VLOOKUP(B31,Table1[],4)) -> #N/A | M31: 1 | N31: =IF(L31="timber",B31,"") -> #N/A | O31: =IF(D31="y",B31,"") | P31: =IF(F31="y",B31,"") | Q31: =IF(B31="","",ISNUMBER(FIND("Dead wood",B31:B910))) | R31: 1 | Y31: {=INDEX($N$21:$N$900, MATCH(0, COUNTIF($Y$2:Y30, $N$21:$N$900), 0))} -> #N/A | AC31: {=INDEX($O$21:$O$900, MATCH(0, COUNTIF($AC$2:AC30, $O$21:$O$900), 0))} -> #N/A | AG31: {=INDEX($P$21:$P$900, MATCH(0, COUNTIF($AG$2:AG30, $P$21:$P$900), 0))} -> #N/A
A32: ='PSP Data'!A35 -> 0 | B32: =IF('PSP Data'!B35=0,"",'PSP Data'!B35) | C32: ='PSP Data'!C35 -> 0 | D32: ='PSP Data'!D35 -> 0 | E32: ='PSP Data'!E35 -> 0 | F32: ='PSP Data'!F35 -> 0 | G32: ='PSP Data'!G35 -> 0 | H32: ='PSP Data'!H35 -> 0 | I32: ='PSP Data'!I35 -> 0 | J32: =IF(C32>=25,C32,#N/A) -> #N/A | K32: =IF(AND((A32<'PSP Data'!$C$11),(A32<>0)),Analysis!C32,#N/A) -> #N/A | L32: =IF(VLOOKUP(B32,Table1[],4)=0,"unknown", VLOOKUP(B32,Table1[],4)) -> #N/A | M32: 1 | N32: =IF(L32="timber",B32,"") -> #N/A | O32: =IF(D32="y",B32,"") | P32: =IF(F32="y",B32,"") | Q32: =IF(B32="","",ISNUMBER(FIND("Dead wood",B32:B911))) | R32: 1 | Y32: {=INDEX($N$21:$N$900, MATCH(0, COUNTIF($Y$2:Y31, $N$21:$N$900), 0))} -> #N/A | AC32: {=INDEX($O$21:$O$900, MATCH(0, COUNTIF($AC$2:AC31, $O$21:$O$900), 0))} -> #N/A | AG32: {=INDEX($P$21:$P$900, MATCH(0, COUNTIF($AG$2:AG31, $P$21:$P$900), 0))} -> #N/A
... A44: ='PSP Data'!A47 -> 0 | B44: =IF('PSP Data'!B47=0,"",'PSP Data'!B47) | C44: ='PSP Data'!C47 -> 0 | D44: ='PSP Data'!D47 -> 0 | E44: ='PSP Data'!E47 -> 0 | F44: ='PSP Data'!F47 -> 0 | G44: ='PSP Data'!G47 -> 0 | H44: ='PSP Data'!H47 -> 0 | I44: ='PSP Data'!I47 -> 0 | J44: =IF(C44>=25,C44,#N/A) -> #N/A | K44: =IF(AND((A44<'PSP Data'!$C$11),(A44<>0)),Analysis!C44,#N/A) -> #N/A | L44: =IF(VLOOKUP(B44,Table1[],4)=0,"unknown", VLOOKUP(B44,Table1[],4)) -> #N/A | M44: 1 | N44: =IF(L44="timber",B44,"") -> #N/A | O44: =IF(D44="y",B44,"") | P44: =IF(F44="y",B44,"") | Q44: =IF(B44="","",ISNUMBER(FIND("Dead wood",B44:B923))) | R44: 1 | Y44: {=INDEX($N$21:$N$900, MATCH(0, COUNTIF($Y$2:Y43, $N$21:$N$900), 0))} -> #N/A | AC44: {=INDEX($O$21:$O$900, MATCH(0, COUNTIF($AC$2:AC43, $O$21:$O$900), 0))} -> #N/A | AG44: {=INDEX($P$21:$P$900, MATCH(0, COUNTIF($AG$2:AG43, $P$21:$P$900), 0))} -> #N/A
A45: ='PSP Data'!A48 -> 0 | B45: =IF('PSP Data'!B48=0,"",'PSP Data'!B48) | C45: ='PSP Data'!C48 -> 0 | D45: ='PSP Data'!D48 -> 0 | E45: ='PSP Data'!E48 -> 0 | F45: ='PSP Data'!F48 -> 0 | G45: ='PSP Data'!G48 -> 0 | H45: ='PSP Data'!H48 -> 0 | I45: ='PSP Data'!I48 -> 0 | J45: =IF(C45>=25,C45,#N/A) -> #N/A | K45: =IF(AND((A45<'PSP Data'!$C$11),(A45<>0)),Analysis!C45,#N/A) -> #N/A | L45: =IF(VLOOKUP(B45,Table1[],4)=0,"unknown", VLOOKUP(B45,Table1[],4)) -> #N/A | M45: 1 | N45: =IF(L45="timber",B45,"") -> #N/A | O45: =IF(D45="y",B45,"") | P45: =IF(F45="y",B45,"") | Q45: =IF(B45="","",ISNUMBER(FIND("Dead wood",B45:B924))) | R45: 1
A46: ='PSP Data'!A49 -> 0 | B46: =IF('PSP Data'!B49=0,"",'PSP Data'!B49) | C46: ='PSP Data'!C49 -> 0 | D46: ='PSP Data'!D49 -> 0 | E46: ='PSP Data'!E49 -> 0 | F46: ='PSP Data'!F49 -> 0 | G46: ='PSP Data'!G49 -> 0 | H46: ='PSP Data'!H49 -> 0 | I46: ='PSP Data'!I49 -> 0 | J46: =IF(C46>=25,C46,#N/A) -> #N/A | K46: =IF(AND((A46<'PSP Data'!$C$11),(A46<>0)),Analysis!C46,#N/A) -> #N/A | L46: =IF(VLOOKUP(B46,Table1[],4)=0,"unknown", VLOOKUP(B46,Table1[],4)) -> #N/A | M46: 1 | N46: =IF(L46="timber",B46,"") -> #N/A | O46: =IF(D46="y",B46,"") | P46: =IF(F46="y",B46,"") | Q46: =IF(B46="","",ISNUMBER(FIND("Dead wood",B46:B925))) | R46: 1
A47: ='PSP Data'!A50 -> 0 | B47: =IF('PSP Data'!B50=0,"",'PSP Data'!B50) | C47: ='PSP Data'!C50 -> 0 | D47: ='PSP Data'!D50 -> 0 | E47: ='PSP Data'!E50 -> 0 | F47: ='PSP Data'!F50 -> 0 | G47: ='PSP Data'!G50 -> 0 | H47: ='PSP Data'!H50 -> 0 | I47: ='PSP Data'!I50 -> 0 | J47: =IF(C47>=25,C47,#N/A) -> #N/A | K47: =IF(AND((A47<'PSP Data'!$C$11),(A47<>0)),Analysis!C47,#N/A) -> #N/A | L47: =IF(VLOOKUP(B47,Table1[],4)=0,"unknown", VLOOKUP(B47,Table1[],4)) -> #N/A | M47: 1 | N47: =IF(L47="timber",B47,"") -> #N/A | O47: =IF(D47="y",B47,"") | P47: =IF(F47="y",B47,"") | Q47: =IF(B47="","",ISNUMBER(FIND("Dead wood",B47:B926))) | R47: 1
A48: ='PSP Data'!A51 -> 0 | B48: =IF('PSP Data'!B51=0,"",'PSP Data'!B51) | C48: ='PSP Data'!C51 -> 0 | D48: ='PSP Data'!D51 -> 0 | E48: ='PSP Data'!E51 -> 0 | F48: ='PSP Data'!F51 -> 0 | G48: ='PSP Data'!G51 -> 0 | H48: ='PSP Data'!H51 -> 0 | I48: ='PSP Data'!I51 -> 0 | J48: =IF(C48>=25,C48,#N/A) -> #N/A | K48: =IF(AND((A48<'PSP Data'!$C$11),(A48<>0)),Analysis!C48,#N/A) -> #N/A | L48: =IF(VLOOKUP(B48,Table1[],4)=0,"unknown", VLOOKUP(B48,Table1[],4)) -> #N/A | M48: 1 | N48: =IF(L48="timber",B48,"") -> #N/A | O48: =IF(D48="y",B48,"") | P48: =IF(F48="y",B48,"") | Q48: =IF(B48="","",ISNUMBER(FIND("Dead wood",B48:B927))) | R48: 1
A49: ='PSP Data'!A52 -> 0 | B49: =IF('PSP Data'!B52=0,"",'PSP Data'!B52) | C49: ='PSP Data'!C52 -> 0 | D49: ='PSP Data'!D52 -> 0 | E49: ='PSP Data'!E52 -> 0 | F49: ='PSP Data'!F52 -> 0 | G49: ='PSP Data'!G52 -> 0 | H49: ='PSP Data'!H52 -> 0 | I49: ='PSP Data'!I52 -> 0 | J49: =IF(C49>=25,C49,#N/A) -> #N/A | K49: =IF(AND((A49<'PSP Data'!$C$11),(A49<>0)),Analysis!C49,#N/A) -> #N/A | L49: =IF(VLOOKUP(B49,Table1[],4)=0,"unknown", VLOOKUP(B49,Table1[],4)) -> #N/A | M49: 1 | N49: =IF(L49="timber",B49,"") -> #N/A | O49: =IF(D49="y",B49,"") | P49: =IF(F49="y",B49,"") | Q49: =IF(B49="","",ISNUMBER(FIND("Dead wood",B49:B928))) | R49: 1
A50: ='PSP Data'!A53 -> 0 | B50: =IF('PSP Data'!B53=0,"",'PSP Data'!B53) | C50: ='PSP Data'!C53 -> 0 | D50: ='PSP Data'!D53 -> 0 | E50: ='PSP Data'!E53 -> 0 | F50: ='PSP Data'!F53 -> 0 | G50: ='PSP Data'!G53 -> 0 | H50: ='PSP Data'!H53 -> 0 | I50: ='PSP Data'!I53 -> 0 | J50: =IF(C50>=25,C50,#N/A) -> #N/A | K50: =IF(AND((A50<'PSP Data'!$C$11),(A50<>0)),Analysis!C50,#N/A) -> #N/A | L50: =IF(VLOOKUP(B50,Table1[],4)=0,"unknown", VLOOKUP(B50,Table1[],4)) -> #N/A | M50: 1 | N50: =IF(L50="timber",B50,"") -> #N/A | O50: =IF(D50="y",B50,"") | P50: =IF(F50="y",B50,"") | Q50: =IF(B50="","",ISNUMBER(FIND("Dead wood",B50:B929))) | R50: 1
A51: ='PSP Data'!A54 -> 0 | B51: =IF('PSP Data'!B54=0,"",'PSP Data'!B54) | C51: ='PSP Data'!C54 -> 0 | D51: ='PSP Data'!D54 -> 0 | E51: ='PSP Data'!E54 -> 0 | F51: ='PSP Data'!F54 -> 0 | G51: ='PSP Data'!G54 -> 0 | H51: ='PSP Data'!H54 -> 0 | I51: ='PSP Data'!I54 -> 0 | J51: =IF(C51>=25,C51,#N/A) -> #N/A | K51: =IF(AND((A51<'PSP Data'!$C$11),(A51<>0)),Analysis!C51,#N/A) -> #N/A | L51: =IF(VLOOKUP(B51,Table1[],4)=0,"unknown", VLOOKUP(B51,Table1[],4)) -> #N/A | M51: 1 | N51: =IF(L51="timber",B51,"") -> #N/A | O51: =IF(D51="y",B51,"") | P51: =IF(F51="y",B51,"") | Q51: =IF(B51="","",ISNUMBER(FIND("Dead wood",B51:B930))) | R51: 1
...

Sheet Lists
A1: Scientific name | B1: Popular name | C1: Lookup name | D1: Category | F1: Tree Category | H1: Binary | J1: Dead Wood Classes | K1: Description [Winrock 2013] - The machete test consists of raising the machete up to shoulder height and allowing it come down to the dead wood piece with the force of gravity. No additional force should be applied to the motion of the machete.
A2: Acacia collinsi | B2: cockspur | C2: =Table1[[#This Row],[Scientific name]]&" ("&Table1[[#This Row],[Popular name]]&")" -> Acacia collinsi (cockspur) | D2: habitat | F2: habitat | H2: y | J2: sound | K2: If the machete does not sink into the piece (bounces off), classify it as sound.
A3: Acoelorraphe wrightii | B3: Palmeto | C3: =Table1[[#This Row],[Scientific name]]&" ("&Table1[[#This Row],[Popular name]]&")" -> Acoelorraphe wrightii (Palmeto) | D3: habitat | F3: timber | H3: n | J3: intermediate | K3: If the machete sinks partly into the piece, and there has been some wood loss, classify it as intermediate.
A4: Aspidosperma cruentum | B4: My lady | C4: =Table1[[#This Row],[Scientific name]]&" ("&Table1[[#This Row],[Popular name]]&")" -> Aspidosperma cruentum (My lady) | D4: timber | F4: medicinal | J4: rotten | K4: If the machete sticks into the piece, if there is more extensive wood loss, and the piece is crumbly, classify as rotten.
A5: Astoronium graveolens | B5: Jobillo | C5: =Table1[[#This Row],[Scientific name]]&" ("&Table1[[#This Row],[Popular name]]&")" -> Astoronium graveolens (Jobillo) | D5: habitat
A6: Astronium graveolens | B6: Jobillo | C6: =Table1[[#This Row],[Scientific name]]&" ("&Table1[[#This Row],[Popular name]]&")" -> Astronium graveolens (Jobillo) | D6: timber
A7: Attalea cohune | B7: Cohune palm | C7: =Table1[[#This Row],[Scientific name]]&" ("&Table1[[#This Row],[Popular name]]&")" -> Attalea cohune (Cohune palm) | D7: habitat
A8: Avicenia germinans | B8: Black mangrove | C8: =Table1[[#This Row],[Scientific name]]&" ("&Table1[[#This Row],[Popular name]]&")" -> Avicenia germinans (Black mangrove) | D8: habitat
A9: Bactris major | B9: Pokenoboy | C9: =Table1[[#This Row],[Scientific name]]&" ("&Table1[[#This Row],[Popular name]]&")" -> Bactris major (Pokenoboy) | D9: habitat
A10: Bauhinia divaricata | B10: cow foot | C10: =Table1[[#This Row],[Scientific name]]&" ("&Table1[[#This Row],[Popular name]]&")" -> Bauhinia divaricata (cow foot) | D10: habitat
A11: Bourreria mollis | B11: Wild craboo | C11: =Table1[[#This Row],[Scientific name]]&" ("&Table1[[#This Row],[Popular name]]&")" -> Bourreria mollis (Wild craboo) | D11: habitat
A12: Brossimium alicastrum | B12: Ramon | C12: =Table1[[#This Row],[Scientific name]]&" ("&Table1[[#This Row],[Popular name]]&")" -> Brossimium alicastrum (Ramon) | D12: habitat
A13: Bucida buceras | B13: Bullet tree | C13: =Table1[[#This Row],[Scientific name]]&" ("&Table1[[#This Row],[Popular name]]&")" -> Bucida buceras (Bullet tree) | D13: timber
A14: Bursera simaruba | B14: Red gumbolimbo | C14: =Table1[[#This Row],[Scientific name]]&" ("&Table1[[#This Row],[Popular name]]&")" -> Bursera simaruba (Red gumbolimbo) | D14: medicinal
A15: Bysornima bucidaefolia | B15: Sak paj | C15: =Table1[[#This Row],[Scientific name]]&" ("&Table1[[#This Row],[Popular name]]&")" -> Bysornima bucidaefolia (Sak paj) | D15: habitat
A16: Caesalpina gaumeri | B16: Warree wood | C16: =Table1[[#This Row],[Scientific name]]&" ("&Table1[[#This Row],[Popular name]]&")" -> Caesalpina gaumeri (Warree wood) | D16: timber
... A27: Coccoloba belizensis | B27: Grande betty | C27: =Table1[[#This Row],[Scientific name]]&" ("&Table1[[#This Row],[Popular name]]&")" -> Coccoloba belizensis (Grande betty) | D27: habitat
A28: Coccoloba diversifolia | B28: Bob small leaf | C28: =Table1[[#This Row],[Scientific name]]&" ("&Table1[[#This Row],[Popular name]]&")" -> Coccoloba diversifolia (Bob small leaf)
A29: Coccothrinax argentata | B29: Silver palm | C29: =Table1[[#This Row],[Scientific name]]&" ("&Table1[[#This Row],[Popular name]]&")" -> Coccothrinax argentata (Silver palm) | D29: habitat
A30: Cojoba graciliflora | B30: John crow bead | C30: =Table1[[#This Row],[Scientific name]]&" ("&Table1[[#This Row],[Popular name]]&")" -> Cojoba graciliflora (John crow bead) | D30: habitat
A31: Conocarpus erectus | B31: Boton wood | C31: =Table1[[#This Row],[Scientific name]]&" ("&Table1[[#This Row],[Popular name]]&")" -> Conocarpus erectus (Boton wood ) | D31: habitat
A32: Cordia dodecandra | B32: Ziricote | C32: =Table1[[#This Row],[Scientific name]]&" ("&Table1[[#This Row],[Popular name]]&")" -> Cordia dodecandra (Ziricote) | D32: timber
A33: Cordia sebestena | B33: Ziricote | C33: =Table1[[#This Row],[Scientific name]]&" ("&Table1[[#This Row],[Popular name]]&")" -> Cordia sebestena (Ziricote) | D33: timber
A34: Crescentia cujete | B34: Calabash | C34: =Table1[[#This Row],[Scientific name]]&" ("&Table1[[#This Row],[Popular name]]&")" -> Crescentia cujete (Calabash) | D34: habitat
A35: Crysophila stauracantha | B35: Give and take | C35: =Table1[[#This Row],[Scientific name]]&" ("&Table1[[#This Row],[Popular name]]&")" -> Crysophila stauracantha (Give and take) | D35: habitat
A36: Dead wood | B36: CLASS 1 | C36: =Table1[[#This Row],[Scientific name]]&" ("&Table1[[#This Row],[Popular name]]&")" -> Dead wood (CLASS 1) | D36: habitat
A37: Dead wood | B37: CLASS 2 | C37: =Table1[[#This Row],[Scientific name]]&" ("&Table1[[#This Row],[Popular name]]&")" -> Dead wood (CLASS 2) | D37: habitat
A38: Delonix regia | B38: Flamboiant tree | C38: =Table1[[#This Row],[Scientific name]]&" ("&Table1[[#This Row],[Popular name]]&")" -> Delonix regia (Flamboiant tree) | D38: habitat
A39: Dendropandax arboreus | B39: White gumbolimbo | C39: =Table1[[#This Row],[Scientific name]]&" ("&Table1[[#This Row],[Popular name]]&")" -> Dendropandax arboreus (White gumbolimbo) | D39: timber
A40: Diospirus salcifolia | B40: cyril | C40: =Table1[[#This Row],[Scientific name]]&" ("&Table1[[#This Row],[Popular name]]&")" -> Diospirus salcifolia (cyril) | D40: habitat
... A44: Enterolobium cyclocarpum | B44: Guanacaste | C44: =Table1[[#This Row],[Scientific name]]&" ("&Table1[[#This Row],[Popular name]]&")" -> Enterolobium cyclocarpum (Guanacaste) | D44: timber
A45: Erythoxylum guatemalensis | B45: Chokche | C45: =Table1[[#This Row],[Scientific name]]&" ("&Table1[[#This Row],[Popular name]]&")" -> Erythoxylum guatemalensis (Chokche)
A46: Exothea diphylla | B46: uayamcox | C46: =Table1[[#This Row],[Scientific name]]&" ("&Table1[[#This Row],[Popular name]]&")" -> Exothea diphylla (uayamcox) | D46: habitat
A47: ficus sp. | B47: Ficus | C47: =Table1[[#This Row],[Scientific name]]&" ("&Table1[[#This Row],[Popular name]]&")" -> ficus sp. (Ficus) | D47: habitat
A48: Ficus sp. Obtusifolia | B48: Amate matapalo | C48: =Table1[[#This Row],[Scientific name]]&" ("&Table1[[#This Row],[Popular name]]&")" -> Ficus sp. Obtusifolia (Amate matapalo) | D48: habitat
A49: Gaussia maya | B49: Maya palm | C49: =Table1[[#This Row],[Scientific name]]&" ("&Table1[[#This Row],[Popular name]]&")" -> Gaussia maya (Maya palm) | D49: habitat
A50: Gliricidia sepium | B50: Madre cacoa | C50: =Table1[[#This Row],[Scientific name]]&" ("&Table1[[#This Row],[Popular name]]&")" -> Gliricidia sepium (Madre cacoa) | D50: timber
A51: Guazuma ulmifolia | B51: Bay cedar | C51: =Table1[[#This Row],[Scientific name]]&" ("&Table1[[#This Row],[Popular name]]&")" -> Guazuma ulmifolia (Bay cedar) | D51: habitat
A52: Guettarda combsii | B52: Glassy wood | C52: =Table1[[#This Row],[Scientific name]]&" ("&Table1[[#This Row],[Popular name]]&")" -> Guettarda combsii (Glassy wood) | D52: habitat
A53: Gymnathes lucida | B53: Pi | C53: =Table1[[#This Row],[Scientific name]]&" ("&Table1[[#This Row],[Popular name]]&")" -> Gymnathes lucida (Pi ) | D53: timber
...
